{
 "cells": [
  {
   "cell_type": "code",
   "execution_count": 4,
   "metadata": {},
   "outputs": [],
   "source": [
    "from data import *\n",
    "from model import *\n",
    "from params import *\n",
    "from preprocessing import *"
   ]
  },
  {
   "cell_type": "code",
   "execution_count": 13,
   "metadata": {},
   "outputs": [],
   "source": [
    "import numpy as np\n",
    "import cv2\n",
    "import matplotlib.pyplot as plt\n",
    "from tensorflow.keras.preprocessing import image"
   ]
  },
  {
   "cell_type": "code",
   "execution_count": 6,
   "metadata": {},
   "outputs": [],
   "source": [
    "img = cv2.imread('/home/roisin/code/dorwein/ai_weeder/raw_data/images/Common wheat/1.png', 0)"
   ]
  },
  {
   "cell_type": "code",
   "execution_count": 7,
   "metadata": {},
   "outputs": [
    {
     "name": "stdout",
     "output_type": "stream",
     "text": [
      "Load latest model from local registry...\n",
      "Load latest model from disk...\n"
     ]
    },
    {
     "name": "stderr",
     "output_type": "stream",
     "text": [
      "2024-09-05 14:44:54.888657: W tensorflow/stream_executor/platform/default/dso_loader.cc:64] Could not load dynamic library 'libcuda.so.1'; dlerror: libcuda.so.1: cannot open shared object file: No such file or directory; LD_LIBRARY_PATH: /home/roisin/.pyenv/versions/3.10.6/envs/ai_weeder/lib/python3.10/site-packages/cv2/../../lib64:/usr/local/lib:/home/roisin/software/heasoft-6.31.1src/heasoft-6.31.1/x86_64-pc-linux-gnu-libc2.35/lib\n",
      "2024-09-05 14:44:54.888686: W tensorflow/stream_executor/cuda/cuda_driver.cc:263] failed call to cuInit: UNKNOWN ERROR (303)\n",
      "2024-09-05 14:44:54.888705: I tensorflow/stream_executor/cuda/cuda_diagnostics.cc:156] kernel driver does not appear to be running on this host (roisin-ThinkPad-E15): /proc/driver/nvidia/version does not exist\n",
      "2024-09-05 14:44:54.888954: I tensorflow/core/platform/cpu_feature_guard.cc:193] This TensorFlow binary is optimized with oneAPI Deep Neural Network Library (oneDNN) to use the following CPU instructions in performance-critical operations:  AVX2 FMA\n",
      "To enable them in other operations, rebuild TensorFlow with the appropriate compiler flags.\n"
     ]
    },
    {
     "name": "stdout",
     "output_type": "stream",
     "text": [
      "✅ Model loaded from local disk\n"
     ]
    }
   ],
   "source": [
    "model = load_model()"
   ]
  },
  {
   "cell_type": "code",
   "execution_count": 9,
   "metadata": {},
   "outputs": [],
   "source": [
    "img = resize_and_expand(img, 224, 224)"
   ]
  },
  {
   "cell_type": "code",
   "execution_count": 14,
   "metadata": {},
   "outputs": [],
   "source": [
    "img_path = '/home/roisin/code/dorwein/ai_weeder/raw_data/images/Common wheat/1.png'\n",
    "img_tf = image.load_img(img_path, target_size=(224, 224))"
   ]
  },
  {
   "cell_type": "code",
   "execution_count": 16,
   "metadata": {},
   "outputs": [
    {
     "data": {
      "text/plain": [
       "(224, 224, 3)"
      ]
     },
     "execution_count": 16,
     "metadata": {},
     "output_type": "execute_result"
    }
   ],
   "source": [
    "np.shape(img_tf)"
   ]
  },
  {
   "cell_type": "code",
   "execution_count": 11,
   "metadata": {},
   "outputs": [
    {
     "data": {
      "text/plain": [
       "(1, 224, 224)"
      ]
     },
     "execution_count": 11,
     "metadata": {},
     "output_type": "execute_result"
    }
   ],
   "source": [
    "img_tf = vgg16_preproc(img_t)\n",
    "np.shape(img)"
   ]
  },
  {
   "cell_type": "code",
   "execution_count": 12,
   "metadata": {},
   "outputs": [
    {
     "name": "stdout",
     "output_type": "stream",
     "text": [
      "WARNING:tensorflow:Model was constructed with shape (None, 224, 224, 3) for input KerasTensor(type_spec=TensorSpec(shape=(None, 224, 224, 3), dtype=tf.float32, name='vgg16_input'), name='vgg16_input', description=\"created by layer 'vgg16_input'\"), but it was called on an input with incompatible shape (None, 224, 224).\n",
      "WARNING:tensorflow:Model was constructed with shape (None, 224, 224, 3) for input KerasTensor(type_spec=TensorSpec(shape=(None, 224, 224, 3), dtype=tf.float32, name='input_4'), name='input_4', description=\"created by layer 'input_4'\"), but it was called on an input with incompatible shape (None, 224, 224).\n"
     ]
    },
    {
     "ename": "ValueError",
     "evalue": "in user code:\n\n    File \"/home/roisin/.pyenv/versions/3.10.6/envs/ai_weeder/lib/python3.10/site-packages/keras/engine/training.py\", line 2041, in predict_function  *\n        return step_function(self, iterator)\n    File \"/home/roisin/.pyenv/versions/3.10.6/envs/ai_weeder/lib/python3.10/site-packages/keras/engine/training.py\", line 2027, in step_function  **\n        outputs = model.distribute_strategy.run(run_step, args=(data,))\n    File \"/home/roisin/.pyenv/versions/3.10.6/envs/ai_weeder/lib/python3.10/site-packages/keras/engine/training.py\", line 2015, in run_step  **\n        outputs = model.predict_step(data)\n    File \"/home/roisin/.pyenv/versions/3.10.6/envs/ai_weeder/lib/python3.10/site-packages/keras/engine/training.py\", line 1983, in predict_step\n        return self(x, training=False)\n    File \"/home/roisin/.pyenv/versions/3.10.6/envs/ai_weeder/lib/python3.10/site-packages/keras/utils/traceback_utils.py\", line 70, in error_handler\n        raise e.with_traceback(filtered_tb) from None\n    File \"/home/roisin/.pyenv/versions/3.10.6/envs/ai_weeder/lib/python3.10/site-packages/keras/engine/input_spec.py\", line 250, in assert_input_compatibility\n        raise ValueError(\n\n    ValueError: Exception encountered when calling layer \"vgg16\" \"                 f\"(type Functional).\n    \n    Input 0 of layer \"block1_conv1\" is incompatible with the layer: expected min_ndim=4, found ndim=3. Full shape received: (None, 224, 224)\n    \n    Call arguments received by layer \"vgg16\" \"                 f\"(type Functional):\n      • inputs=tf.Tensor(shape=(None, 224, 224), dtype=float32)\n      • training=False\n      • mask=None\n",
     "output_type": "error",
     "traceback": [
      "\u001b[0;31m---------------------------------------------------------------------------\u001b[0m",
      "\u001b[0;31mValueError\u001b[0m                                Traceback (most recent call last)",
      "Cell \u001b[0;32mIn[12], line 1\u001b[0m\n\u001b[0;32m----> 1\u001b[0m \u001b[43mpredict\u001b[49m\u001b[43m(\u001b[49m\u001b[43mmodel\u001b[49m\u001b[43m,\u001b[49m\u001b[43m \u001b[49m\u001b[43mimg\u001b[49m\u001b[43m)\u001b[49m\n",
      "File \u001b[0;32m~/code/dorwein/ai_weeder/ai_weeder_package/model.py:38\u001b[0m, in \u001b[0;36mpredict\u001b[0;34m(model, img)\u001b[0m\n\u001b[1;32m     32\u001b[0m \u001b[38;5;28;01mdef\u001b[39;00m \u001b[38;5;21mpredict\u001b[39m(model, img):\n\u001b[1;32m     34\u001b[0m \u001b[38;5;250m    \u001b[39m\u001b[38;5;124;03m'''\u001b[39;00m\n\u001b[1;32m     35\u001b[0m \u001b[38;5;124;03m    Get a prediction from the loaded model, UNTESTED\u001b[39;00m\n\u001b[1;32m     36\u001b[0m \u001b[38;5;124;03m    '''\u001b[39;00m\n\u001b[0;32m---> 38\u001b[0m     pred \u001b[38;5;241m=\u001b[39m \u001b[43mmodel\u001b[49m\u001b[38;5;241;43m.\u001b[39;49m\u001b[43mpredict\u001b[49m\u001b[43m(\u001b[49m\u001b[43mimg\u001b[49m\u001b[43m)\u001b[49m\n\u001b[1;32m     40\u001b[0m     \u001b[38;5;66;03m# Getting class label\u001b[39;00m\n\u001b[1;32m     41\u001b[0m     predicted_class_key \u001b[38;5;241m=\u001b[39m np\u001b[38;5;241m.\u001b[39margmax(pred, axis\u001b[38;5;241m=\u001b[39m\u001b[38;5;241m1\u001b[39m)[\u001b[38;5;241m0\u001b[39m]\n",
      "File \u001b[0;32m~/.pyenv/versions/3.10.6/envs/ai_weeder/lib/python3.10/site-packages/keras/utils/traceback_utils.py:70\u001b[0m, in \u001b[0;36mfilter_traceback.<locals>.error_handler\u001b[0;34m(*args, **kwargs)\u001b[0m\n\u001b[1;32m     67\u001b[0m     filtered_tb \u001b[38;5;241m=\u001b[39m _process_traceback_frames(e\u001b[38;5;241m.\u001b[39m__traceback__)\n\u001b[1;32m     68\u001b[0m     \u001b[38;5;66;03m# To get the full stack trace, call:\u001b[39;00m\n\u001b[1;32m     69\u001b[0m     \u001b[38;5;66;03m# `tf.debugging.disable_traceback_filtering()`\u001b[39;00m\n\u001b[0;32m---> 70\u001b[0m     \u001b[38;5;28;01mraise\u001b[39;00m e\u001b[38;5;241m.\u001b[39mwith_traceback(filtered_tb) \u001b[38;5;28;01mfrom\u001b[39;00m \u001b[38;5;28;01mNone\u001b[39;00m\n\u001b[1;32m     71\u001b[0m \u001b[38;5;28;01mfinally\u001b[39;00m:\n\u001b[1;32m     72\u001b[0m     \u001b[38;5;28;01mdel\u001b[39;00m filtered_tb\n",
      "File \u001b[0;32m/tmp/__autograph_generated_filey5ijurzp.py:15\u001b[0m, in \u001b[0;36mouter_factory.<locals>.inner_factory.<locals>.tf__predict_function\u001b[0;34m(iterator)\u001b[0m\n\u001b[1;32m     13\u001b[0m \u001b[38;5;28;01mtry\u001b[39;00m:\n\u001b[1;32m     14\u001b[0m     do_return \u001b[38;5;241m=\u001b[39m \u001b[38;5;28;01mTrue\u001b[39;00m\n\u001b[0;32m---> 15\u001b[0m     retval_ \u001b[38;5;241m=\u001b[39m ag__\u001b[38;5;241m.\u001b[39mconverted_call(ag__\u001b[38;5;241m.\u001b[39mld(step_function), (ag__\u001b[38;5;241m.\u001b[39mld(\u001b[38;5;28mself\u001b[39m), ag__\u001b[38;5;241m.\u001b[39mld(iterator)), \u001b[38;5;28;01mNone\u001b[39;00m, fscope)\n\u001b[1;32m     16\u001b[0m \u001b[38;5;28;01mexcept\u001b[39;00m:\n\u001b[1;32m     17\u001b[0m     do_return \u001b[38;5;241m=\u001b[39m \u001b[38;5;28;01mFalse\u001b[39;00m\n",
      "\u001b[0;31mValueError\u001b[0m: in user code:\n\n    File \"/home/roisin/.pyenv/versions/3.10.6/envs/ai_weeder/lib/python3.10/site-packages/keras/engine/training.py\", line 2041, in predict_function  *\n        return step_function(self, iterator)\n    File \"/home/roisin/.pyenv/versions/3.10.6/envs/ai_weeder/lib/python3.10/site-packages/keras/engine/training.py\", line 2027, in step_function  **\n        outputs = model.distribute_strategy.run(run_step, args=(data,))\n    File \"/home/roisin/.pyenv/versions/3.10.6/envs/ai_weeder/lib/python3.10/site-packages/keras/engine/training.py\", line 2015, in run_step  **\n        outputs = model.predict_step(data)\n    File \"/home/roisin/.pyenv/versions/3.10.6/envs/ai_weeder/lib/python3.10/site-packages/keras/engine/training.py\", line 1983, in predict_step\n        return self(x, training=False)\n    File \"/home/roisin/.pyenv/versions/3.10.6/envs/ai_weeder/lib/python3.10/site-packages/keras/utils/traceback_utils.py\", line 70, in error_handler\n        raise e.with_traceback(filtered_tb) from None\n    File \"/home/roisin/.pyenv/versions/3.10.6/envs/ai_weeder/lib/python3.10/site-packages/keras/engine/input_spec.py\", line 250, in assert_input_compatibility\n        raise ValueError(\n\n    ValueError: Exception encountered when calling layer \"vgg16\" \"                 f\"(type Functional).\n    \n    Input 0 of layer \"block1_conv1\" is incompatible with the layer: expected min_ndim=4, found ndim=3. Full shape received: (None, 224, 224)\n    \n    Call arguments received by layer \"vgg16\" \"                 f\"(type Functional):\n      • inputs=tf.Tensor(shape=(None, 224, 224), dtype=float32)\n      • training=False\n      • mask=None\n"
     ]
    }
   ],
   "source": [
    "predict(model, img)"
   ]
  }
 ],
 "metadata": {
  "kernelspec": {
   "display_name": "ai_weeder",
   "language": "python",
   "name": "python3"
  },
  "language_info": {
   "codemirror_mode": {
    "name": "ipython",
    "version": 3
   },
   "file_extension": ".py",
   "mimetype": "text/x-python",
   "name": "python",
   "nbconvert_exporter": "python",
   "pygments_lexer": "ipython3",
   "version": "3.10.6"
  }
 },
 "nbformat": 4,
 "nbformat_minor": 2
}
